{
  "status": "fail",
  "tests": [
    {
      "message": "An unexpected error occurred:\nclojure.lang.ArityException: Wrong number of args (1) passed to: sci.impl.fns/fun/arity-0--3486",
      "name": "one",
      "status": "error",
      "test_code": "(is (= [] (prime-factors/of 1)))"
    },
    {
      "message": "An unexpected error occurred:\nclojure.lang.ArityException: Wrong number of args (1) passed to: sci.impl.fns/fun/arity-0--3486",
      "name": "two",
      "status": "error",
      "test_code": "(is (= [2] (prime-factors/of 2)))"
    },
    {
      "message": "An unexpected error occurred:\nclojure.lang.ArityException: Wrong number of args (1) passed to: sci.impl.fns/fun/arity-0--3486",
      "name": "three",
      "status": "error",
      "test_code": "(is (= [3] (prime-factors/of 3)))"
    },
    {
      "message": "An unexpected error occurred:\nclojure.lang.ArityException: Wrong number of args (1) passed to: sci.impl.fns/fun/arity-0--3486",
      "name": "four",
      "status": "error",
      "test_code": "(is (= [2 2] (prime-factors/of 4)))"
    },
    {
      "message": "An unexpected error occurred:\nclojure.lang.ArityException: Wrong number of args (1) passed to: sci.impl.fns/fun/arity-0--3486",
      "name": "six",
      "status": "error",
      "test_code": "(is (= [2 3] (prime-factors/of 6)))"
    },
    {
      "message": "An unexpected error occurred:\nclojure.lang.ArityException: Wrong number of args (1) passed to: sci.impl.fns/fun/arity-0--3486",
      "name": "eight",
      "status": "error",
      "test_code": "(is (= [2 2 2] (prime-factors/of 8)))"
    },
    {
      "message": "An unexpected error occurred:\nclojure.lang.ArityException: Wrong number of args (1) passed to: sci.impl.fns/fun/arity-0--3486",
      "name": "nine",
      "status": "error",
      "test_code": "(is (= [3 3] (prime-factors/of 9)))"
    },
    {
      "message": "An unexpected error occurred:\nclojure.lang.ArityException: Wrong number of args (1) passed to: sci.impl.fns/fun/arity-0--3486",
      "name": "twenty-seven",
      "status": "error",
      "test_code": "(is (= [3 3 3] (prime-factors/of 27)))"
    },
    {
      "message": "An unexpected error occurred:\nclojure.lang.ArityException: Wrong number of args (1) passed to: sci.impl.fns/fun/arity-0--3486",
      "name": "six-hundred-twenty-five",
      "status": "error",
      "test_code": "(is (= [5 5 5 5] (prime-factors/of 625)))"
    },
    {
      "message": "An unexpected error occurred:\nclojure.lang.ArityException: Wrong number of args (1) passed to: sci.impl.fns/fun/arity-0--3486",
      "name": "a-large-number",
      "status": "error",
      "test_code": "(is (= [5 17 23 461] (prime-factors/of 901255)))"
    },
    {
      "message": "An unexpected error occurred:\nclojure.lang.ArityException: Wrong number of args (1) passed to: sci.impl.fns/fun/arity-0--3486",
      "name": "a-huge-number",
      "status": "error",
      "test_code": "(is (= [11 9539 894119] (prime-factors/of 93819012551)))"
    }
  ],
  "version": 2
}
