{
  "status": "fail",
  "tests": [
    {
      "message": "An unexpected error occurred:\nclojure.lang.ArityException: Wrong number of args (2) passed to: sci.impl.fns/fun/arity-0--3486",
      "name": "empty-sequence",
      "status": "error",
      "test_code": "(is (empty? (retain even? (quote ()))))"
    },
    {
      "message": "An unexpected error occurred:\nclojure.lang.ArityException: Wrong number of args (2) passed to: sci.impl.fns/fun/arity-0--3486",
      "name": "empty-retain",
      "status": "error",
      "test_code": "(is (empty? (retain odd? [2 4 6 8 10])))"
    },
    {
      "message": "An unexpected error occurred:\nclojure.lang.ArityException: Wrong number of args (2) passed to: sci.impl.fns/fun/arity-0--3486",
      "name": "retain-single-element",
      "status": "error",
      "test_code": "(is (= [0] (retain even? [0])))"
    },
    {
      "message": "An unexpected error occurred:\nclojure.lang.ArityException: Wrong number of args (2) passed to: sci.impl.fns/fun/arity-0--3486",
      "name": "retain-several",
      "status": "error",
      "test_code": "(is (= [1 3 5] (retain odd? (range 6))))"
    },
    {
      "message": "An unexpected error occurred:\nclojure.lang.ArityException: Wrong number of args (2) passed to: sci.impl.fns/fun/arity-0--3486",
      "name": "retain-everything",
      "status": "error",
      "test_code": "(is (= [2 4 6 8 10] (retain even? [2 4 6 8 10])))"
    },
    {
      "message": "An unexpected error occurred:\nclojure.lang.ArityException: Wrong number of args (2) passed to: sci.impl.fns/fun/arity-0--3486",
      "name": "retain-strings",
      "status": "error",
      "test_code": "(is (= [\"string\" \"three\"] (retain string? [\"string\" 1 :two \"three\" [\"4\"]])))"
    },
    {
      "message": "An unexpected error occurred:\nclojure.lang.ArityException: Wrong number of args (2) passed to: sci.impl.fns/fun/arity-0--3486",
      "name": "empty-discard",
      "status": "error",
      "test_code": "(is (empty? (discard even? [2 4 6 8 10])))"
    },
    {
      "message": "An unexpected error occurred:\nclojure.lang.ArityException: Wrong number of args (2) passed to: sci.impl.fns/fun/arity-0--3486",
      "name": "discard-first",
      "status": "error",
      "test_code": "(is (= [1 2] (discard zero? [0 1 2])))"
    },
    {
      "message": "An unexpected error occurred:\nclojure.lang.ArityException: Wrong number of args (2) passed to: sci.impl.fns/fun/arity-0--3486",
      "name": "discard-last",
      "status": "error",
      "test_code": "(is (= [2 1] (discard zero? [2 1 0])))"
    },
    {
      "message": "An unexpected error occurred:\nclojure.lang.ArityException: Wrong number of args (2) passed to: sci.impl.fns/fun/arity-0--3486",
      "name": "discard-several",
      "status": "error",
      "test_code": "(is (= [0 2 4] (discard odd? (range 6))))"
    },
    {
      "message": "An unexpected error occurred:\nWrong number of args (2) passed to: function of arity 0",
      "name": "does-not-use-existing-implementations",
      "status": "error",
      "test_code": "(with-redefs [filter (fn-throw-exception \"Implement without filter!\") remove (fn-throw-exception \"Implement without remove!\") filterv (fn-throw-exception \"Implement without filterv!\")] (dorun (retain even? (range 10))) (dorun (discard even? (range 10))))"
    }
  ],
  "version": 3
}
